// throw and catch error

try {
    let a ;
    console.log(a.length);
    console.log("hi there from inside");
}
catch (e)
{
    console.log(e);
}

console.log("hi there");